Workbook

Sheet Sheet1 - Given Sheet
A1: Order_ID | B1: Customer_ID | C1: Order_Date | D1: Region | E1: Category | F1: Product | G1: Quantity | H1: Unit_Price | I1: Total_Amount | J1: Product_ID
A2: 1 | B2: CUST1083 | C2: 45394 | D2: West | E2: Books | F2: Notebook | G2: 8 | H2: 3033.43 | I2: 24267.44 | J2: P001
A3: 2 | B3: CUST1024 | C3: 45506 | D3: East | E3: Fashion | F3: Jacket | G3: 5 | H3: 3045.46 | I3: 15227.3 | J3: P002
A4: 3 | B4: CUST1038 | C4: 45422 | D4: South | E4: Books | F4: Comics | G4: 8 | H4: 4178.97 | I4: 33431.76 | J4: P003
A5: 4 | B5: CUST1089 | C5: 45483 | D5: West | E5: Books | F5: Novel | G5: 6 | H5: 134.62 | I5: 807.72 | J5: P004
A6: 5 | B6: CUST1064 | C6: 45340 | D6: East | E6: Fashion | F6: Sneakers | G6: 3 | H6: 1974.06 | I6: 5922.18 | J6: P005
A7: 6 | B7: CUST1018 | C7: 45422 | D7: North | E7: Fashion | F7: Sneakers | G7: 5 | H7: 2307.45 | I7: 11537.25 | J7: P005
A8: 7 | B8: CUST1002 | C8: 45380 | D8: West | E8: Home Appliances | F8: Refrigerator | G8: 9 | H8: 178.23 | I8: 1604.07 | J8: P006
A9: 8 | B9: CUST1078 | C9: 45383 | D9: East | E9: Groceries | F9: Bread | G9: 8 | H9: 268.5 | I9: 2148 | J9: P007
A10: 9 | B10: CUST1006 | C10: 45372 | D10: West | E10: Home Appliances | F10: Blender | G10: 4 | H10: 1627.38 | I10: 6509.52 | J10: P008
A11: 10 | B11: CUST1034 | C11: 45345 | D11: South | E11: Groceries | F11: Milk | G11: 2 | H11: 3898.15 | I11: 7796.3 | J11: P009
A12: 11 | B12: CUST1062 | C12: 45493 | D12: South | E12: Groceries | F12: Milk | G12: 8 | H12: 2895.18 | I12: 23161.44 | J12: P009
A13: 12 | B13: CUST1089 | C13: 45587 | D13: North | E13: Books | F13: Comics | G13: 5 | H13: 2975.08 | I13: 14875.4 | J13: P003
... A501: 500 | B501: CUST1041 | C501: 45565 | D501: West | E501: Electronics | F501: Headphones | G501: 8 | H501: 4212.76 | I501: 33702.08 | J501: P016

Sheet Analysis
A1: Total Revenue | B1: =ROUND(SUM('Sheet1 - Given Sheet'!I:I),2) -> 6263982.2
A2: Average Order Value | B2: =AVERAGE('Sheet1 - Given Sheet'!I:I) -> 12527.964
A4: Sales by Products
A5: Comics | B5: =SUMIF('Sheet1 - Given Sheet'!$F:$F, "Comics", 'Sheet1 - Given Sheet'!$I:$I) -> 473835.59
A6: Rice | B6: =SUMIF('Sheet1 - Given Sheet'!$F:$F, "Rice", 'Sheet1 - Given Sheet'!$I:$I) -> 405999.28
A7: Headphones | B7: =SUMIF('Sheet1 - Given Sheet'!$F:$F, "Headphones", 'Sheet1 - Given Sheet'!$I:$I) -> 391800.59
A8: Magazine | B8: =SUMIF('Sheet1 - Given Sheet'!$F:$F, "Magazine", 'Sheet1 - Given Sheet'!$I:$I) -> 361813.98
A9: T-shirt | B9: =SUMIF('Sheet1 - Given Sheet'!$F:$F, "T-shirt", 'Sheet1 - Given Sheet'!$I:$I) -> 349824.67
A12: Top 3 Customers by Purchase Value
A13: Customer_ID | B13: Total_Purchase_value
A14: CUST1062 | B14: 179209
A15: CUST1003 | B15: 160072.99
A16: CUST1075 | B16: 144563.81

Sheet Product by Sales
A2: Product by Sales
A3: Row Labels | B3: Total_Amount_by_product
A4: Comics | B4: 473835.59
A5: Rice | B5: 405999.28
A6: Headphones | B6: 391800.59
A7: Magazine | B7: 361813.98
A8: T-shirt | B8: 349824.67
A9: Bread | B9: 333193.93
A10: Refrigerator | B10: 329406.1
A11: Smartphone | B11: 325972.68
A12: Milk | B12: 319898.74
A13: Eggs | B13: 312136.78
A14: Novel | B14: 307370.1
A15: Notebook | B15: 305853.5
... A24: Grand Total | B24: 6263982.2

Sheet MOM_Growth
A1: Sales Per month
A2: Month | B2: Total_Sales | C2: MoM_Growth(%) | F2: Sales by Customers
F3: Row Labels | G3: Sum of Total_Amount
A4: 2024-01 | B4: =SUMIFS('Sheet1 - Given Sheet'!$I:$I, 'Sheet1 - Given Sheet'!$C:$C, ">="&DATE(2024,1,1), 'Sheet1 - Given Sheet'!$C:$C, "<"&DATE(2024,2,1)) -> 796530.74 | C4: 0 | F4: CUST1062 | G4: 179209
A5: 2024-02 | B5: =SUMIFS('Sheet1 - Given Sheet'!$I:$I, 'Sheet1 - Given Sheet'!$C:$C, ">="&DATE(2024,2,1), 'Sheet1 - Given Sheet'!$C:$C, "<"&DATE(2024,3,1)) -> 579576.01 | C5: =((B5-B4)/B5)*100 -> -37.433352 | F5: CUST1003 | G5: 160072.99
A6: 2024-03 | B6: =SUMIFS('Sheet1 - Given Sheet'!$I:$I, 'Sheet1 - Given Sheet'!$C:$C, ">="&DATE(2024,3,1), 'Sheet1 - Given Sheet'!$C:$C, "<"&DATE(2024,4,1)) -> 527151.06 | C6: =((B6-B5)/B6)*100 -> -9.9449577 | F6: CUST1075 | G6: 144563.81
A7: 2024-04 | B7: =SUMIFS('Sheet1 - Given Sheet'!$I:$I, 'Sheet1 - Given Sheet'!$C:$C, ">="&DATE(2024,4,1), 'Sheet1 - Given Sheet'!$C:$C, "<"&DATE(2024,5,1)) -> 603609.11 | C7: =((B7-B6)/B7)*100 -> 12.666815 | F7: CUST1019 | G7: 143915.18
A8: 2024-05 | B8: =SUMIFS('Sheet1 - Given Sheet'!$I:$I, 'Sheet1 - Given Sheet'!$C:$C, ">="&DATE(2024,5,1), 'Sheet1 - Given Sheet'!$C:$C, "<"&DATE(2024,6,1)) -> 605913.9 | C8: =((B8-B7)/B8)*100 -> 0.38038243 | F8: CUST1033 | G8: 142289.3
A9: 2024-06 | B9: =SUMIFS('Sheet1 - Given Sheet'!$I:$I, 'Sheet1 - Given Sheet'!$C:$C, ">="&DATE(2024,6,1), 'Sheet1 - Given Sheet'!$C:$C, "<"&DATE(2024,7,1)) -> 700538.82 | C9: =((B9-B8)/B9)*100 -> 13.507448 | F9: CUST1038 | G9: 135642.19
A10: 2024-07 | B10: =SUMIFS('Sheet1 - Given Sheet'!$I:$I, 'Sheet1 - Given Sheet'!$C:$C, ">="&DATE(2024,7,1), 'Sheet1 - Given Sheet'!$C:$C, "<"&DATE(2024,8,1)) -> 487514.8 | C10: =((B10-B9)/B10)*100 -> -43.695908 | F10: CUST1012 | G10: 121761.27
A11: 2024-08 | B11: =SUMIFS('Sheet1 - Given Sheet'!$I:$I, 'Sheet1 - Given Sheet'!$C:$C, ">="&DATE(2024,8,1), 'Sheet1 - Given Sheet'!$C:$C, "<"&DATE(2024,9,1)) -> 584660.41 | C11: =((B11-B10)/B11)*100 -> 16.615733 | F11: CUST1043 | G11: 118090.68
A12: 2024-09 | B12: =SUMIFS('Sheet1 - Given Sheet'!$I:$I, 'Sheet1 - Given Sheet'!$C:$C, ">="&DATE(2024,9,1), 'Sheet1 - Given Sheet'!$C:$C, "<"&DATE(2024,10,1)) -> 730754.04 | C12: =((B12-B11)/B12)*100 -> 19.992175 | F12: CUST1047 | G12: 110716.74
A13: 2024-10 | B13: =SUMIFS('Sheet1 - Given Sheet'!$I:$I, 'Sheet1 - Given Sheet'!$C:$C, ">="&DATE(2024,10,1), 'Sheet1 - Given Sheet'!$C:$C, "<"&DATE(2024,11,1)) -> 647733.27 | C13: =((B13-B12)/B13)*100 -> -12.817123 | F13: CUST1068 | G13: 108083.44
A14: 2024-11 | B14: =SUMIFS('Sheet1 - Given Sheet'!$I:$I, 'Sheet1 - Given Sheet'!$C:$C, ">="&DATE(2024,11,1), 'Sheet1 - Given Sheet'!$C:$C, "<"&DATE(2024,12,1)) -> 0 | C14: =((B14-B13)/B14)*100 -> #DIV/0! | F14: CUST1024 | G14: 106797.79
A15: 2024-12 | B15: =SUMIFS('Sheet1 - Given Sheet'!$I:$I, 'Sheet1 - Given Sheet'!$C:$C, ">="&DATE(2024,12,1), 'Sheet1 - Given Sheet'!$C:$C, "<="&DATE(2024,12,31)) -> 0 | C15: =((B15-B14)/B15)*100 -> #DIV/0! | F15: CUST1086 | G15: 106004.98
F16: CUST1002 | G16: 102003.7
F17: CUST1089 | G17: 101773.27
F18: CUST1074 | G18: 101348.18
F19: CUST1041 | G19: 95176.55
F20: CUST1046 | G20: 94053.43
F21: CUST1084 | G21: 93800.94
F22: CUST1053 | G22: 92952.59
F23: CUST1045 | G23: 91530.71
F24: CUST1099 | G24: 88580.89
F25: CUST1027 | G25: 87899.11
F26: CUST1055 | G26: 84641.33
F27: CUST1025 | G27: 82126.18
... F104: Grand Total | G104: 6263982.2

Sheet Product_IDs Lookup Sheet
A1: Product_ID | B1: Category | C1: Product
A2: P001 | B2: =IFERROR(INDEX('Sheet1 - Given Sheet'!$E:$E, MATCH(A2, 'Sheet1 - Given Sheet'!$J:$J, 0)), "Not Found") -> Books | C2: Notebooks
A3: P002 | B3: =IFERROR(INDEX('Sheet1 - Given Sheet'!$E:$E, MATCH(A3, 'Sheet1 - Given Sheet'!$J:$J, 0)), "Not Found") -> Fashion | C3: Jacket
A4: P003 | B4: =IFERROR(INDEX('Sheet1 - Given Sheet'!$E:$E, MATCH(A4, 'Sheet1 - Given Sheet'!$J:$J, 0)), "Not Found") -> Books | C4: Comics
A5: P004 | B5: =IFERROR(INDEX('Sheet1 - Given Sheet'!$E:$E, MATCH(A5, 'Sheet1 - Given Sheet'!$J:$J, 0)), "Not Found") -> Books | C5: Novel
A6: P005 | B6: =IFERROR(INDEX('Sheet1 - Given Sheet'!$E:$E, MATCH(A6, 'Sheet1 - Given Sheet'!$J:$J, 0)), "Not Found") -> Fashion | C6: Sneakers
A7: P006 | B7: =IFERROR(INDEX('Sheet1 - Given Sheet'!$E:$E, MATCH(A7, 'Sheet1 - Given Sheet'!$J:$J, 0)), "Not Found") -> Home Appliances | C7: Refrigerator
A8: P007 | B8: =IFERROR(INDEX('Sheet1 - Given Sheet'!$E:$E, MATCH(A8, 'Sheet1 - Given Sheet'!$J:$J, 0)), "Not Found") -> Groceries | C8: Bread
A9: P008 | B9: =IFERROR(INDEX('Sheet1 - Given Sheet'!$E:$E, MATCH(A9, 'Sheet1 - Given Sheet'!$J:$J, 0)), "Not Found") -> Home Appliances | C9: Blendor
A10: P009 | B10: =IFERROR(INDEX('Sheet1 - Given Sheet'!$E:$E, MATCH(A10, 'Sheet1 - Given Sheet'!$J:$J, 0)), "Not Found") -> Groceries | C10: Milk
A11: P010 | B11: =IFERROR(INDEX('Sheet1 - Given Sheet'!$E:$E, MATCH(A11, 'Sheet1 - Given Sheet'!$J:$J, 0)), "Not Found") -> Groceries | C11: Rice
A12: P011 | B12: =IFERROR(INDEX('Sheet1 - Given Sheet'!$E:$E, MATCH(A12, 'Sheet1 - Given Sheet'!$J:$J, 0)), "Not Found") -> Electronics | C12: Smartwatch
A13: P012 | B13: =IFERROR(INDEX('Sheet1 - Given Sheet'!$E:$E, MATCH(A13, 'Sheet1 - Given Sheet'!$J:$J, 0)), "Not Found") -> Fashion | C13: T-shirt
... A21: P020 | B21: =IFERROR(INDEX('Sheet1 - Given Sheet'!$E:$E, MATCH(A21, 'Sheet1 - Given Sheet'!$J:$J, 0)), "Not Found") -> Electronics | C21: Smartphone

Sheet Price Lookup
A1: Product | B1: Product_ID | C1: Average_Unit_Price
A2: Notebook | B2: =IFERROR(INDEX('Sheet1 - Given Sheet'!$J:$J, MATCH(A2, 'Sheet1 - Given Sheet'!$F:$F, 0)), "Not Found") -> P001 | C2: =AVERAGEIF('Sheet1 - Given Sheet'!$F:$F, A2, 'Sheet1 - Given Sheet'!$H:$H) -> 2224.9945
A3: Jacket | B3: =IFERROR(INDEX('Sheet1 - Given Sheet'!$J:$J, MATCH(A3, 'Sheet1 - Given Sheet'!$F:$F, 0)), "Not Found") -> P002 | C3: =AVERAGEIF('Sheet1 - Given Sheet'!$F:$F, A3, 'Sheet1 - Given Sheet'!$H:$H) -> 2422.1348
A4: Comics | B4: =IFERROR(INDEX('Sheet1 - Given Sheet'!$J:$J, MATCH(A4, 'Sheet1 - Given Sheet'!$F:$F, 0)), "Not Found") -> P003 | C4: =AVERAGEIF('Sheet1 - Given Sheet'!$F:$F, A4, 'Sheet1 - Given Sheet'!$H:$H) -> 2726.3779
A5: Novel | B5: =IFERROR(INDEX('Sheet1 - Given Sheet'!$J:$J, MATCH(A5, 'Sheet1 - Given Sheet'!$F:$F, 0)), "Not Found") -> P004 | C5: =AVERAGEIF('Sheet1 - Given Sheet'!$F:$F, A5, 'Sheet1 - Given Sheet'!$H:$H) -> 2355.4436
A6: Sneakers | B6: =IFERROR(INDEX('Sheet1 - Given Sheet'!$J:$J, MATCH(A6, 'Sheet1 - Given Sheet'!$F:$F, 0)), "Not Found") -> P005 | C6: =AVERAGEIF('Sheet1 - Given Sheet'!$F:$F, A6, 'Sheet1 - Given Sheet'!$H:$H) -> 2600.0176
A7: Refrigerator | B7: =IFERROR(INDEX('Sheet1 - Given Sheet'!$J:$J, MATCH(A7, 'Sheet1 - Given Sheet'!$F:$F, 0)), "Not Found") -> P006 | C7: =AVERAGEIF('Sheet1 - Given Sheet'!$F:$F, A7, 'Sheet1 - Given Sheet'!$H:$H) -> 2660.6129
A8: Bread | B8: =IFERROR(INDEX('Sheet1 - Given Sheet'!$J:$J, MATCH(A8, 'Sheet1 - Given Sheet'!$F:$F, 0)), "Not Found") -> P007 | C8: =AVERAGEIF('Sheet1 - Given Sheet'!$F:$F, A8, 'Sheet1 - Given Sheet'!$H:$H) -> 2641.33
A9: Blender | B9: =IFERROR(INDEX('Sheet1 - Given Sheet'!$J:$J, MATCH(A9, 'Sheet1 - Given Sheet'!$F:$F, 0)), "Not Found") -> P008 | C9: =AVERAGEIF('Sheet1 - Given Sheet'!$F:$F, A9, 'Sheet1 - Given Sheet'!$H:$H) -> 2389.4929
A10: Milk | B10: =IFERROR(INDEX('Sheet1 - Given Sheet'!$J:$J, MATCH(A10, 'Sheet1 - Given Sheet'!$F:$F, 0)), "Not Found") -> P009 | C10: =AVERAGEIF('Sheet1 - Given Sheet'!$F:$F, A10, 'Sheet1 - Given Sheet'!$H:$H) -> 2514.7392
A11: Rice | B11: =IFERROR(INDEX('Sheet1 - Given Sheet'!$J:$J, MATCH(A11, 'Sheet1 - Given Sheet'!$F:$F, 0)), "Not Found") -> P010 | C11: =AVERAGEIF('Sheet1 - Given Sheet'!$F:$F, A11, 'Sheet1 - Given Sheet'!$H:$H) -> 2124.3063
A12: Smartwatch | B12: =IFERROR(INDEX('Sheet1 - Given Sheet'!$J:$J, MATCH(A12, 'Sheet1 - Given Sheet'!$F:$F, 0)), "Not Found") -> P011 | C12: =AVERAGEIF('Sheet1 - Given Sheet'!$F:$F, A12, 'Sheet1 - Given Sheet'!$H:$H) -> 2255.1473
A13: T-shirt | B13: =IFERROR(INDEX('Sheet1 - Given Sheet'!$J:$J, MATCH(A13, 'Sheet1 - Given Sheet'!$F:$F, 0)), "Not Found") -> P012 | C13: =AVERAGEIF('Sheet1 - Given Sheet'!$F:$F, A13, 'Sheet1 - Given Sheet'!$H:$H) -> 2647.906
... A21: Smartphone | B21: =IFERROR(INDEX('Sheet1 - Given Sheet'!$J:$J, MATCH(A21, 'Sheet1 - Given Sheet'!$F:$F, 0)), "Not Found") -> P020 | C21: =AVERAGEIF('Sheet1 - Given Sheet'!$F:$F, A21, 'Sheet1 - Given Sheet'!$H:$H) -> 2328.5689
G22: Average Price | H22: =SUM(C2:C21) -> 49903.669

Sheet Sales by Category and Region
A1: Sales by Category and Region
A3: Sum of Total_Amount | B3: Column Labels
A4: Row Labels | B4: East | C4: North | D4: South | E4: West | F4: (blank) | G4: Grand Total
A5: Books | B5: 340957.76 | C5: 331455.76 | D5: 451937.72 | E5: 324521.93 | G5: 1448873.2
A6: Groceries | B6: 444162.66 | C6: 341875.08 | D6: 280981.2 | E6: 304209.79 | G6: 1371228.7
A7: Electronics | B7: 221287.39 | C7: 273441.22 | D7: 399405.21 | E7: 310164.02 | G7: 1204297.8
A8: Fashion | B8: 261842.67 | C8: 327099.66 | D8: 262410.29 | E8: 291772.37 | G8: 1143125
A9: Home Appliances | B9: 262002.23 | C9: 225956.35 | D9: 308484.57 | E9: 300014.28 | G9: 1096457.4
A10: (blank)
A11: Grand Total | B11: 1530252.7 | C11: 1499828.1 | D11: 1703219 | E11: 1530682.4 | G11: 6263982.2

Sheet Visulaization
A2: Sales Distribution by Region
A3: Row Labels | B3: Sum of Total_Amount
A4: East | B4: 1530252.7
A5: North | B5: 1499828.1
A6: South | B6: 1703219
A7: West | B7: 1530682.4
A8: (blank)
A9: Grand Total | B9: 6263982.2
A18: Month wise Sales Trend
A20: Row Labels | B20: Sum of Total_Sales | C20: Sum of MoM_Growth(%)
A21: 2024-01 | B21: 796530.74 | C21: 0
A22: 2024-02 | B22: 579576.01 | C22: -37.433352
A23: 2024-03 | B23: 527151.06 | C23: -9.9449577
A24: 2024-04 | B24: 603609.11 | C24: 12.666815
A25: 2024-05 | B25: 605913.9 | C25: 0.38038243
A26: 2024-06 | B26: 700538.82 | C26: 13.507448
A27: 2024-07 | B27: 487514.8 | C27: -43.695908
A28: 2024-08 | B28: 584660.41 | C28: 16.615733
A29: 2024-09 | B29: 730754.04 | C29: 19.992175
A30: 2024-10 | B30: 647733.27 | C30: -12.817123
A31: 2024-11 | B31: 0 | C31: #DIV/0!
A32: 2024-12 | B32: 0 | C32: #DIV/0!
A33: (blank)
A34: Grand Total | B34: 6263982.2 | C34: #DIV/0!
A38: Sales by Category
A40: Row Labels | B40: Sum of Total_Amount
A41: Books | B41: 1448873.2
A42: Groceries | B42: 1371228.7
A43: Electronics | B43: 1204297.8
A44: Fashion | B44: 1143125
A45: Home Appliances | B45: 1096457.4
A46: (blank)
A47: Grand Total | B47: 6263982.2
A55: Top 5 Products
A56: Row Labels | B56: Sum of Total_Amount
A57: Comics | B57: 473835.59
A58: Rice | B58: 405999.28
A59: Headphones | B59: 391800.59
A60: Magazine | B60: 361813.98
A61: T-shirt | B61: 349824.67
...

Sheet Dashboard

Sheet Key Insights and Analysis 
A2: Total Revenue | B2: =ROUND(SUM('Sheet1 - Given Sheet'!I:I),2) -> 6263982.2
A3: Analysis Period | B3: Jan 2024 - Oct 2024
A5: Top Performing Regions | B5: South
A6: Contribution(in %) | B6: 27.19
A8: Best Selling Category | B8: Books
A9: Total Sales | B9: 1448873.2
A11: Top 5 Products and their Sales
A12: Products | B12: Total_Amount_by_product
A13: Comics | B13: 473835.59
A14: Rice | B14: 405999.28
A15: Headphones | B15: 391800.59
A16: Magazine | B16: 361813.98
A17: T-shirt | B17: 349824.67
A19: Month over Month Growth
A20: Highest Growth in Month | B20: Sept 2024 (~20%)
A21: Highest Descline in Month | B21: Feb 2024 (-37.43%)
A22: Overall Trend | B22: Steady then plummeting
A24: Customer Behaviour
A25: Top Customer spent | B25: CUST1062
A26: Average Order Value of Products | B26: 49903.67
A28: Category Performance
A29: Books | B29: 0.2313
A30: Electronics | B30: 0.1922
A32: Seasonal Patterns
A33: Peak Sales Month | B33: January
A34: Lowest Sales Month | B34: July
